Workbook

Sheet Calendar
A1: Date | B1: Time | C1: Event | D1: Location | E1: Notes
A2: 46277 | B2: 6:00 PM - 8:00 PM | C2: Parent Open House | D2: TBD
A3: 46278 | B3: 10:00 AM - 2:00 PM | C3: Onsite Uniform Ordering & BSA Applications | D3: Hype Athletics
A4: 46279 | B4: 9:00 PM - 10:30 PM | C4: Dhulfiqār Leader Meeting (EC or GA) | D4: 27112 N Pleasant Ridge Dearborn Heights, MI 48127
A5: 46286 | B5: 8:00 PM - 10:30 PM | C5: Leader Orientation | D5: TBD | E5: Is this needed if we have the retreat?
A6: 46290 | B6: 0.79166667 | C6: Leader Retreat/Camp | D6: TBD
A7: 46291 | B7: All day | C7: Leader Retreat/Camp | D7: TBD
A8: 46292 | B8: 0.5 | C8: Leader Retreat/Camp | D8: TBD
A9: 46293 | B9: 9:00 PM - 10:30 PM | C9: Dhulfiqār Leader Meeting (EC or GA) | D9: 27112 N Pleasant Ridge Dearborn Heights, MI 48127
A10: 46297 | B10: 6:30 PM - 9:00 PM | C10: Dhulfiqār Scouting Program | E10: First
A11: 46300 | B11: 9:00 PM - 10:30 PM | C11: Dhulfiqār Leader Meeting (EC or GA) | D11: 27112 N Pleasant Ridge Dearborn Heights, MI 48127
A12: 46301 | B12: 7:30 PM - 8:30 PM | C12: Dhulfiqār Youth Program | D12: Highview Elementary School25225 Richardson St, Dearborn Heights, MI 48127 | E12: First
A13: 46304 | B13: 6:30 PM - 9:00 PM | C13: Dhulfiqār Scouting Program | D13: Highview Elementary School25225 Richardson St, Dearborn Heights, MI 48127
A14: 46307 | B14: 9:00 PM - 10:30 PM | C14: Dhulfiqār Leader Meeting (EC or GA) | D14: 27112 N Pleasant Ridge Dearborn Heights, MI 48127
A15: 46308 | B15: 7:30 PM - 8:30 PM | C15: Dhulfiqār Youth Program
A16: 46311 | B16: 6:30 PM - 9:00 PM | C16: Dhulfiqār Scouting Program
A17: 46314 | B17: 9:00 PM - 10:30 PM | C17: Dhulfiqār Leader Meeting (EC or GA) | D17: 27112 N Pleasant Ridge Dearborn Heights, MI 48127
A18: 46315 | B18: 7:30 PM - 8:30 PM | C18: Dhulfiqār Youth Program | E18: Youth Majlis Martyrdom Sayyidah Fatemah (as)
A19: 46318 | B19: 6:30 PM - 9:00 PM | C19: Dhulfiqār Scouting Program
A20: 46321 | B20: 9:00 PM - 10:30 PM | C20: Dhulfiqār Leader Meeting (EC or GA) | D20: 27112 N Pleasant Ridge Dearborn Heights, MI 48127
A21: 46322 | B21: 7:30 PM - 8:30 PM | C21: Dhulfiqār Youth Program
A22: 46325 | B22: 5:00 PM | C22: Dhulfiqār Scout Camp | D22: D' BAR A
A23: 46326 | B23: All day | C23: Dhulfiqār Scout Camp | D23: D' BAR A
A24: 46327 | B24: 1:30 PM | C24: Dhulfiqār Scout Camp | D24: D' BAR A
A25: 46328 | B25: 9:00 PM - 10:30 PM | C25: Dhulfiqār Leader Meeting (EC or GA) | D25: 27112 N Pleasant Ridge Dearborn Heights, MI 48127
A26: 46329 | B26: 7:30 PM - 8:30 PM | C26: Dhulfiqār Youth Program
A27: 46332 | B27: 6:30 PM - 9:00 PM | C27: Dhulfiqār Scouting Program
A28: 46335 | B28: 9:00 PM - 10:30 PM | C28: Dhulfiqār Leader Meeting (EC or GA) | D28: TBD
A29: 46336 | B29: 7:30 PM - 8:30 PM | C29: Dhulfiqār Youth Program
A30: 46339 | B30: 6:30 PM - 9:00 PM | C30: Dhulfiqār Scouting Program
A31: 46342 | B31: 9:00 PM - 10:30 PM | C31: Dhulfiqār Leader Meeting (EC or GA) | D31: TBD
A32: 46343 | B32: 7:30 PM - 8:30 PM | C32: Dhulfiqār Youth Program
A33: 46346 | B33: 6:30 PM - 9:00 PM | C33: Dhulfiqār Scouting Program
A34: 46349 | B34: 9:00 PM - 10:30 PM | C34: Dhulfiqār Leader Meeting (EC or GA) | D34: TBD
A35: 46350 | B35: 7:30 PM - 8:30 PM | C35: Dhulfiqār Youth Program
A36: 46353 | C36: NO Dhulfiqār Scouting Program | E36: (Fall Holiday (Thanksgiving))
A37: 46356 | B37: 9:00 PM - 10:30 PM | C37: Dhulfiqār Leader Meeting (EC or GA) | D37: TBD
A38: 46357 | B38: 7:30 PM - 8:30 PM | C38: Dhulfiqār Youth Program
A39: 46360 | B39: 6:30 PM - 9:00 PM | C39: Dhulfiqār Scouting Program | E39: Birth of Sy. Fatimah (as)
A40: 46363 | B40: 9:00 PM - 10:30 PM | C40: Dhulfiqār Leader Meeting (EC or GA) | D40: TBD
...

Sheet Analysis
B2: Session Type | C2: #
B3: =IFERROR(__xludf.DUMMYFUNCTION("SORT(UNIQUE(FILTER(Calendar!C2:C16,Calendar!C2:C16<>"""")))"),"Dhulfiqār Leader Meeting (EC or GA)") -> Dhulfiqār Leader Meeting (EC or GA) | C3: =COUNTIF(Calendar!C:C,B3) -> 29
B4: =IFERROR(__xludf.DUMMYFUNCTION("""COMPUTED_VALUE"""),"Dhulfiqār Parent-Leader Conferences") -> Dhulfiqār Parent-Leader Conferences | C4: =COUNTIF(Calendar!C:C,B4) -> 1
B5: =IFERROR(__xludf.DUMMYFUNCTION("""COMPUTED_VALUE"""),"Dhulfiqār Scout Camp") -> Dhulfiqār Scout Camp | C5: =COUNTIF(Calendar!C:C,B5) -> 9
B6: =IFERROR(__xludf.DUMMYFUNCTION("""COMPUTED_VALUE"""),"Dhulfiqār Scouting Program") -> Dhulfiqār Scouting Program | C6: =COUNTIF(Calendar!C:C,B6) -> 25
B7: =IFERROR(__xludf.DUMMYFUNCTION("""COMPUTED_VALUE"""),"Dhulfiqār Youth Program") -> Dhulfiqār Youth Program | C7: =COUNTIF(Calendar!C:C,B7) -> 28
B8: =IFERROR(__xludf.DUMMYFUNCTION("""COMPUTED_VALUE"""),"Leader Orientation") -> Leader Orientation | C8: =COUNTIF(Calendar!C:C,B8) -> 1
B9: =IFERROR(__xludf.DUMMYFUNCTION("""COMPUTED_VALUE"""),"Leader Retreat/Camp") -> Leader Retreat/Camp | C9: =COUNTIF(Calendar!C:C,B9) -> 3
B10: =IFERROR(__xludf.DUMMYFUNCTION("""COMPUTED_VALUE"""),"Merit Badge Mania") -> Merit Badge Mania | C10: =COUNTIF(Calendar!C:C,B10) -> 1
B11: =IFERROR(__xludf.DUMMYFUNCTION("""COMPUTED_VALUE"""),"NO Dhulfiqār Scouting Program") -> NO Dhulfiqār Scouting Program | C11: =COUNTIF(Calendar!C:C,B11) -> 9
B12: =IFERROR(__xludf.DUMMYFUNCTION("""COMPUTED_VALUE"""),"NO Dhulfiqār Youth Program") -> NO Dhulfiqār Youth Program | C12: =COUNTIF(Calendar!C:C,B12) -> 8
B13: =IFERROR(__xludf.DUMMYFUNCTION("""COMPUTED_VALUE"""),"Onsite Uniform Ordering & BSA Applications") -> Onsite Uniform Ordering & BSA Applications | C13: =COUNTIF(Calendar!C:C,B13) -> 1
B14: =IFERROR(__xludf.DUMMYFUNCTION("""COMPUTED_VALUE"""),"Parent Open House") -> Parent Open House
B15: Number of distinct weeks
